Workbook

Sheet Dashboard
B2: CHRISTMAN BIG — BID-TO-HIT DASHBOARD ⬛
B4: Structural Concrete Estimation History | Auto-calculated from Estimating tab
B6: Total Bids (excl. Open) | D6: Awarded | F6: Closed (Lost) | H6: Bid-to-Hit Ratio | J6: Avg Bid Amount | L6: Avg Contract (Awarded)
B7: =COUNTIF(Estimating!A2:A200,"Awarded")+COUNTIF(Estimating!A2:A200,"Closed") -> 95 | D7: =COUNTIF(Estimating!A2:A200,"Awarded") -> 19 | F7: =COUNTIF(Estimating!A2:A200,"Closed") -> 76 | H7: =IFERROR(COUNTIF(Estimating!A2:A200,"Awarded")/(COUNTIF(Estimating!A2:A200,"Awarded")+COUNTIF(Estimating!A2:A200,"Closed")),0) -> 0.2 | J7: =IFERROR(AVERAGEIF(Estimating!A2:A200,"<>Open",Estimating!J2:J200),0) -> 2053584.4 | L7: =IFERROR(AVERAGEIF(Estimating!A2:A200,"Awarded",Estimating!N2:N200),0) -> 777297.32
B9: ⬛ HIT RATE BY MARKET SECTOR | H9: ⬛ HIT RATE BY ESTIMATOR
B10: Market Sector | C10: Bids | D10: Awarded | E10: Hit Rate | H10: Estimator | I10: Bids | J10: Awarded | K10: Hit Rate
B11: Church | C11: =COUNTIFS(Estimating!C$2:C$200,B11,Estimating!A$2:A$200,"<>Open") -> 1 | D11: =COUNTIFS(Estimating!C$2:C$200,B11,Estimating!A$2:A$200,"Awarded") -> 0 | E11: =IFERROR(D11/C11,"-") -> 0 | H11: Christian Oglesby | I11: =COUNTIFS(Estimating!M$2:M$200,H11,Estimating!A$2:A$200,"<>Open") -> 2 | J11: =COUNTIFS(Estimating!M$2:M$200,H11,Estimating!A$2:A$200,"Awarded") -> 0 | K11: =IFERROR(J11/I11,"-") -> 0
B12: Elem/High School | C12: =COUNTIFS(Estimating!C$2:C$200,B12,Estimating!A$2:A$200,"<>Open") -> 4 | D12: =COUNTIFS(Estimating!C$2:C$200,B12,Estimating!A$2:A$200,"Awarded") -> 1 | E12: =IFERROR(D12/C12,"-") -> 0.25 | H12: Dave Deller | I12: =COUNTIFS(Estimating!M$2:M$200,H12,Estimating!A$2:A$200,"<>Open") -> 26 | J12: =COUNTIFS(Estimating!M$2:M$200,H12,Estimating!A$2:A$200,"Awarded") -> 5 | K12: =IFERROR(J12/I12,"-") -> 0.19230769
B13: Government | C13: =COUNTIFS(Estimating!C$2:C$200,B13,Estimating!A$2:A$200,"<>Open") -> 28 | D13: =COUNTIFS(Estimating!C$2:C$200,B13,Estimating!A$2:A$200,"Awarded") -> 5 | E13: =IFERROR(D13/C13,"-") -> 0.17857143 | H13: Ethan Conlan | I13: =COUNTIFS(Estimating!M$2:M$200,H13,Estimating!A$2:A$200,"<>Open") -> 9 | J13: =COUNTIFS(Estimating!M$2:M$200,H13,Estimating!A$2:A$200,"Awarded") -> 0 | K13: =IFERROR(J13/I13,"-") -> 0
B14: Health Care | C14: =COUNTIFS(Estimating!C$2:C$200,B14,Estimating!A$2:A$200,"<>Open") -> 6 | D14: =COUNTIFS(Estimating!C$2:C$200,B14,Estimating!A$2:A$200,"Awarded") -> 2 | E14: =IFERROR(D14/C14,"-") -> 0.33333333 | H14: Farzan Rafieyan-Esfahani | I14: =COUNTIFS(Estimating!M$2:M$200,H14,Estimating!A$2:A$200,"<>Open") -> 23 | J14: =COUNTIFS(Estimating!M$2:M$200,H14,Estimating!A$2:A$200,"Awarded") -> 8 | K14: =IFERROR(J14/I14,"-") -> 0.34782609
B15: Higher Ed | C15: =COUNTIFS(Estimating!C$2:C$200,B15,Estimating!A$2:A$200,"<>Open") -> 1 | D15: =COUNTIFS(Estimating!C$2:C$200,B15,Estimating!A$2:A$200,"Awarded") -> 0 | E15: =IFERROR(D15/C15,"-") -> 0 | H15: Frank Duff | I15: =COUNTIFS(Estimating!M$2:M$200,H15,Estimating!A$2:A$200,"<>Open") -> 3 | J15: =COUNTIFS(Estimating!M$2:M$200,H15,Estimating!A$2:A$200,"Awarded") -> 0 | K15: =IFERROR(J15/I15,"-") -> 0
B16: Historic Preservation | C16: =COUNTIFS(Estimating!C$2:C$200,B16,Estimating!A$2:A$200,"<>Open") -> 1 | D16: =COUNTIFS(Estimating!C$2:C$200,B16,Estimating!A$2:A$200,"Awarded") -> 0 | E16: =IFERROR(D16/C16,"-") -> 0 | H16: Greg Klem | I16: =COUNTIFS(Estimating!M$2:M$200,H16,Estimating!A$2:A$200,"<>Open") -> 28 | J16: =COUNTIFS(Estimating!M$2:M$200,H16,Estimating!A$2:A$200,"Awarded") -> 5 | K16: =IFERROR(J16/I16,"-") -> 0.17857143
B17: Industrial/Power | C17: =COUNTIFS(Estimating!C$2:C$200,B17,Estimating!A$2:A$200,"<>Open") -> 29 | D17: =COUNTIFS(Estimating!C$2:C$200,B17,Estimating!A$2:A$200,"Awarded") -> 9 | E17: =IFERROR(D17/C17,"-") -> 0.31034483 | H17: Joseph Leone | I17: =COUNTIFS(Estimating!M$2:M$200,H17,Estimating!A$2:A$200,"<>Open") -> 2 | J17: =COUNTIFS(Estimating!M$2:M$200,H17,Estimating!A$2:A$200,"Awarded") -> 1 | K17: =IFERROR(J17/I17,"-") -> 0.5
B18: Office | C18: =COUNTIFS(Estimating!C$2:C$200,B18,Estimating!A$2:A$200,"<>Open") -> 2 | D18: =COUNTIFS(Estimating!C$2:C$200,B18,Estimating!A$2:A$200,"Awarded") -> 0 | E18: =IFERROR(D18/C18,"-") -> 0 | H18: Ron Cody | I18: =COUNTIFS(Estimating!M$2:M$200,H18,Estimating!A$2:A$200,"<>Open") -> 1 | J18: =COUNTIFS(Estimating!M$2:M$200,H18,Estimating!A$2:A$200,"Awarded") -> 0 | K18: =IFERROR(J18/I18,"-") -> 0
B19: Other | C19: =COUNTIFS(Estimating!C$2:C$200,B19,Estimating!A$2:A$200,"<>Open") -> 10 | D19: =COUNTIFS(Estimating!C$2:C$200,B19,Estimating!A$2:A$200,"Awarded") -> 2 | E19: =IFERROR(D19/C19,"-") -> 0.2 | H19: Sam Peterson | I19: =COUNTIFS(Estimating!M$2:M$200,H19,Estimating!A$2:A$200,"<>Open") -> 1 | J19: =COUNTIFS(Estimating!M$2:M$200,H19,Estimating!A$2:A$200,"Awarded") -> 0 | K19: =IFERROR(J19/I19,"-") -> 0
B20: Parking Deck | C20: =COUNTIFS(Estimating!C$2:C$200,B20,Estimating!A$2:A$200,"<>Open") -> 1 | D20: =COUNTIFS(Estimating!C$2:C$200,B20,Estimating!A$2:A$200,"Awarded") -> 0 | E20: =IFERROR(D20/C20,"-") -> 0
B21: Residential/ Housing | C21: =COUNTIFS(Estimating!C$2:C$200,B21,Estimating!A$2:A$200,"<>Open") -> 7 | D21: =COUNTIFS(Estimating!C$2:C$200,B21,Estimating!A$2:A$200,"Awarded") -> 0 | E21: =IFERROR(D21/C21,"-") -> 0
B22: Retail | C22: =COUNTIFS(Estimating!C$2:C$200,B22,Estimating!A$2:A$200,"<>Open") -> 3 | D22: =COUNTIFS(Estimating!C$2:C$200,B22,Estimating!A$2:A$200,"Awarded") -> 0 | E22: =IFERROR(D22/C22,"-") -> 0
B23: Sports / Event Venues | C23: =COUNTIFS(Estimating!C$2:C$200,B23,Estimating!A$2:A$200,"<>Open") -> 2 | D23: =COUNTIFS(Estimating!C$2:C$200,B23,Estimating!A$2:A$200,"Awarded") -> 0 | E23: =IFERROR(D23/C23,"-") -> 0
B26: ⬛ HIT RATE BY REGION | H26: ⬛ BID VOLUME BY MONTH
B27: Region | C27: Bids | D27: Awarded | E27: Hit Rate | H27: Month | I27: Bids | J27: Awarded | K27: Hit Rate
B28: CCI Central MI | C28: =COUNTIFS(Estimating!B$2:B$200,B28,Estimating!A$2:A$200,"<>Open") -> 51 | D28: =COUNTIFS(Estimating!B$2:B$200,B28,Estimating!A$2:A$200,"Awarded") -> 12 | E28: =IFERROR(D28/C28,"-") -> 0.23529412 | H28: Jan | I28: =COUNTIFS(Estimating!D$2:D$200,1,Estimating!A$2:A$200,"<>Open") -> 7 | J28: =COUNTIFS(Estimating!D$2:D$200,1,Estimating!A$2:A$200,"Awarded") -> 1 | K28: =IFERROR(J28/I28,"-") -> 0.14285714
B29: CCI Southeast MI | C29: =COUNTIFS(Estimating!B$2:B$200,B29,Estimating!A$2:A$200,"<>Open") -> 38 | D29: =COUNTIFS(Estimating!B$2:B$200,B29,Estimating!A$2:A$200,"Awarded") -> 7 | E29: =IFERROR(D29/C29,"-") -> 0.18421053 | H29: Feb | I29: =COUNTIFS(Estimating!D$2:D$200,2,Estimating!A$2:A$200,"<>Open") -> 12 | J29: =COUNTIFS(Estimating!D$2:D$200,2,Estimating!A$2:A$200,"Awarded") -> 6 | K29: =IFERROR(J29/I29,"-") -> 0.5
B30: CCI West Michigan | C30: =COUNTIFS(Estimating!B$2:B$200,B30,Estimating!A$2:A$200,"<>Open") -> 3 | D30: =COUNTIFS(Estimating!B$2:B$200,B30,Estimating!A$2:A$200,"Awarded") -> 0 | E30: =IFERROR(D30/C30,"-") -> 0 | H30: Mar | I30: =COUNTIFS(Estimating!D$2:D$200,3,Estimating!A$2:A$200,"<>Open") -> 4 | J30: =COUNTIFS(Estimating!D$2:D$200,3,Estimating!A$2:A$200,"Awarded") -> 0 | K30: =IFERROR(J30/I30,"-") -> 0
B31: Out of Region | C31: =COUNTIFS(Estimating!B$2:B$200,B31,Estimating!A$2:A$200,"<>Open") -> 3 | D31: =COUNTIFS(Estimating!B$2:B$200,B31,Estimating!A$2:A$200,"Awarded") -> 0 | E31: =IFERROR(D31/C31,"-") -> 0 | H31: Apr | I31: =COUNTIFS(Estimating!D$2:D$200,4,Estimating!A$2:A$200,"<>Open") -> 14 | J31: =COUNTIFS(Estimating!D$2:D$200,4,Estimating!A$2:A$200,"Awarded") -> 2 | K31: =IFERROR(J31/I31,"-") -> 0.14285714
H32: May | I32: =COUNTIFS(Estimating!D$2:D$200,5,Estimating!A$2:A$200,"<>Open") -> 11 | J32: =COUNTIFS(Estimating!D$2:D$200,5,Estimating!A$2:A$200,"Awarded") -> 2 | K32: =IFERROR(J32/I32,"-") -> 0.18181818
H33: Jun | I33: =COUNTIFS(Estimating!D$2:D$200,6,Estimating!A$2:A$200,"<>Open") -> 6 | J33: =COUNTIFS(Estimating!D$2:D$200,6,Estimating!A$2:A$200,"Awarded") -> 2 | K33: =IFERROR(J33/I33,"-") -> 0.33333333
H34: Jul | I34: =COUNTIFS(Estimating!D$2:D$200,7,Estimating!A$2:A$200,"<>Open") -> 9 | J34: =COUNTIFS(Estimating!D$2:D$200,7,Estimating!A$2:A$200,"Awarded") -> 0 | K34: =IFERROR(J34/I34,"-") -> 0
H35: Aug | I35: =COUNTIFS(Estimating!D$2:D$200,8,Estimating!A$2:A$200,"<>Open") -> 5 | J35: =COUNTIFS(Estimating!D$2:D$200,8,Estimating!A$2:A$200,"Awarded") -> 1 | K35: =IFERROR(J35/I35,"-") -> 0.2
H36: Sep | I36: =COUNTIFS(Estimating!D$2:D$200,9,Estimating!A$2:A$200,"<>Open") -> 6 | J36: =COUNTIFS(Estimating!D$2:D$200,9,Estimating!A$2:A$200,"Awarded") -> 1 | K36: =IFERROR(J36/I36,"-") -> 0.16666667
H37: Oct | I37: =COUNTIFS(Estimating!D$2:D$200,10,Estimating!A$2:A$200,"<>Open") -> 5 | J37: =COUNTIFS(Estimating!D$2:D$200,10,Estimating!A$2:A$200,"Awarded") -> 0 | K37: =IFERROR(J37/I37,"-") -> 0
H38: Nov | I38: =COUNTIFS(Estimating!D$2:D$200,11,Estimating!A$2:A$200,"<>Open") -> 8 | J38: =COUNTIFS(Estimating!D$2:D$200,11,Estimating!A$2:A$200,"Awarded") -> 2 | K38: =IFERROR(J38/I38,"-") -> 0.25
H39: Dec | I39: =COUNTIFS(Estimating!D$2:D$200,12,Estimating!A$2:A$200,"<>Open") -> 8 | J39: =COUNTIFS(Estimating!D$2:D$200,12,Estimating!A$2:A$200,"Awarded") -> 2 | K39: =IFERROR(J39/I39,"-") -> 0.25
B42: 📌 HOW TO IMPROVE BID-TO-HIT: Fill in the gold-highlighted columns on the Estimating tab — Delivery Method, Opportunity Source, Go/No-Go Score, Loss Reason, Competitor Who Won, and # of Bidders. Once populated, you can add COUNTIFS breakdowns here (or in a pivot table) to see which delivery methods, opportunity sources, and estimators drive the best win rates. The Bid Delta % column auto-calculates on awarded jobs.

Sheet Estimating
A1: Status | B1: Region | C1: Market Sector | D1: Month | E1: Job # | F1: Estimate # | G1: Name | H1: Bid Date | I1: Sales Date | J1: Bid Amount | K1: Location | L1: Trade | M1: Estimator | N1: Contract Amount | O1: Contract Fee | P1: Contract Hours | Q1: Comments | R1: Conc Vol (CY) | S1: Building SF | T1: Production MH | U1: Installation MH | V1: GC MH | W1: Total MH | X1: Fee | Y1: Duration (PM) Weeks | Z1: Total GC Labor | AA1: Staff Labor Hours | AB1: Total GC's | AC1: GC % | AD1: Customer | AE1: Final Hours | AF1: WIP Est Cost | AG1: WIP Est Fee | AH1: WIP Est Contract | AI1: WIP Fee % | AJ1: Contract Status | AK1: Job Start Date | AL1: Job End Date | AM1: Weeks | AN1: Equipment Value | AO1: Delivery Method | AP1: # of Bidders | AQ1: Opportunity Source | AR1: Go/No-Go Score (1=Low 3=High) | AS1: Loss Reason | AT1: Competitor Who Won | AU1: Our Rank (if lost) | AV1: Bid Delta % (Contract vs Bid)
A2: Awarded | B2: CCI Southeast MI | C2: Health Care | D2: 6 | E2: 251121 | F2: 24-0378 | G2: McKenzie Health System - WC 10 | H2: 6/11/2024 | I2: 9/26/2025 | J2: 1597000 | K2: Sandusky, MI | L2: CON | M2: Greg Klem | N2: 1800550 | O2: 140911 | P2: 9682 | R2: 1525 | S2: 71670 | T2: 6362 | V2: 2440 | W2: 8802 | X2: 144763 | Y2: 14 | Z2: 183489 | AA2: 1680 | AB2: 320044 | AC2: 20% | AD2: The Christman Company - 0 | AE2: 4834.75 | AF2: 1658050 | AG2: 152500 | AH2: 1810550 | AI2: 8.4% | AJ2: Open | AK2: 45139 | AM2: 0 | AN2: 156372 | AO2: Hard Bid | AV2: =IF(A2="Awarded",IFERROR((N2-J2)/J2,"-"),"-") -> 0.12745773
A3: Awarded | B3: CCI Southeast MI | C3: Industrial/Power | D3: 6 | E3: 251039 | F3: 24-0402 | G3: GLWA Final Screened Effluent Pump Station CONCRETE | H3: 6/25/2024 | I3: 4/28/2025 | J3: 3147964 | K3: Detroit, MI | L3: CON | M3: Joseph Leone | N3: 3155940 | O3: 331190 | P3: 15518 | R3: 4413 | S3: 73800 | T3: 12491 | V3: 3027 | W3: 15518 | X3: 331934 | Y3: 32 | Z3: 352947 | AA3: 3072 | AB3: 556823 | AC3: 18% | AD3: FH Paschen - 0 | AE3: 424.5 | AF3: 3131076 | AG3: 195070 | AH3: 3326146 | AI3: 5.9% | AJ3: Open | AK3: 45689 | AM3: 0 | AV3: =IF(A3="Awarded",IFERROR((N3-J3)/J3,"-"),"-") -> 0.0025337011
A4: Awarded | B4: CCI Central MI | C4: Industrial/Power | D4: 11 | E4: 251052 | F4: 24-0718 | G4: Pfizer B41 PSPW & RO System Upgrade - Concrete | H4: 11/19/2024 | I4: 4/28/2025 | J4: 163000 | K4: Portage, MI | L4: CON | M4: Greg Klem | N4: 160800 | O4: 23000 | P4: 942 | R4: 103 | S4: 2716 | T4: 610 | V4: 368 | W4: 978 | X4: 23450 | Y4: 4 | Z4: 30319 | AA4: 264 | AB4: 35236 | AC4: 22% | AD4: The Austin Company - 0 | AE4: 882 | AF4: 147726 | AG4: 24019 | AH4: 171745 | AI4: 14% | AJ4: Open | AK4: 45717 | AM4: 0 | AV4: =IF(A4="Awarded",IFERROR((N4-J4)/J4,"-"),"-") -> -0.013496933
A5: Awarded | B5: CCI Southeast MI | C5: Other | D5: 11 | E5: 251040 | F5: 24-0544 | G5: Woodland Meadows RNG expansion | H5: 11/27/2024 | I5: 4/28/2025 | J5: 1970500 | K5: Wayne, MI | L5: CON | M5: Farzan Rafieyan-Esfahani | N5: 1970500 | O5: 178822 | P5: 10020 | Q5: Revised post bid pricing was submitted to Ameresco on February 20th, 2025 | R5: 2974 | S5: 27945 | T5: 7460 | V5: 2560 | W5: 10020 | X5: 178822 | Y5: 16 | Z5: 202932 | AA5: 1760 | AB5: 255082 | AC5: 13% | AD5: Ameresco - 0 | AE5: 12383 | AF5: 2061537 | AG5: 53571 | AH5: 2115108 | AI5: 2.5% | AJ5: Open | AK5: 45689 | AM5: 0 | AV5: =IF(A5="Awarded",IFERROR((N5-J5)/J5,"-"),"-") -> 0
A6: Awarded | B6: CCI Central MI | C6: Industrial/Power | D6: 12 | E6: 251100 | F6: 24-0792 | G6: Pfizer B41 LSS Crisaborole Mfg | H6: 12/10/2024 | I6: 7/9/2025 | J6: 239000 | K6: Kalamazoo, MI | L6: CON | M6: Dave Deller | N6: 239000 | O6: 20000 | P6: 1357 | R6: 54 | S6: 1390 | T6: 1095 | V6: 262 | W6: 1357 | X6: 20000 | Y6: 4 | Z6: 17087 | AA6: 0 | AB6: 30243 | AC6: 13% | AD6: The Austin Company - 0 | AE6: 2542 | AF6: 346585 | AG6: 139045 | AH6: 485630 | AI6: 28.6% | AJ6: Open | AK6: 45809 | AM6: 0 | AV6: =IF(A6="Awarded",IFERROR((N6-J6)/J6,"-"),"-") -> 0
A7: Awarded | B7: CCI Central MI | C7: Industrial/Power | D7: 12 | F7: 25-1108 | G7: MSU CHP BP4 Structural Concrete | H7: 12/9/2025 | I7: 1/12/2026 | J7: 2897000 | K7: East Lansing, MI | L7: CON | M7: Greg Klem | N7: 2778900 | O7: 189697 | P7: 14621 | R7: 4200 | S7: 35923 | T7: 10468 | V7: 5164 | W7: 15632 | X7: 190423 | Y7: 22 | Z7: 376158 | AA7: 2840 | AB7: 505832 | AC7: 17% | AD7: Granger Construction Company - 0 | AM7: 0 | AN7: 166600 | AV7: =IF(A7="Awarded",IFERROR((N7-J7)/J7,"-"),"-") -> -0.04076631
A8: Open | B8: CCI Central MI | C8: Other | D8: 1 | F8: 26-0009 | G8: GM LGR - Switch House/ Yard , Shipping Yard | H8: 1/8/2026 | J8: 1680368 | K8: Lansing, MI | L8: CON | M8: Tucker Dye | R8: 2375 | T8: 6762 | V8: 2148 | W8: 8910 | X8: 149805 | Y8: 20 | Z8: 217951 | AA8: 0 | AB8: 267796 | AC8: 16% | AD8: Walbridge - 0 | AM8: 0 | AN8: 49559 | AV8: =IF(A8="Awarded",IFERROR((N8-J8)/J8,"-"),"-") -> -
A9: Closed | B9: CCI Central MI | C9: Government | D9: 1 | F9: 26-0008 | G9: Lansing Fire Station No. 8 - Site and Structural Concrete | H9: 1/8/2026 | J9: 438000 | K9: Lansing, MI | L9: CON | M9: Greg Klem | Q9: Alternate 1 - Add $128,000 Alternate 2 - Add $4,000 | R9: 226 | S9: 6633 | T9: 1216 | V9: 1098 | W9: 2314 | X9: 37851 | Y9: 15 | Z9: 76877 | AA9: 720 | AB9: 103226 | AC9: 24% | AD9: The Christman Company - 0 | AM9: 0 | AN9: 70162 | AV9: =IF(A9="Awarded",IFERROR((N9-J9)/J9,"-"),"-") -> -
A10: Closed | B10: CCI Southeast MI | C10: Industrial/Power | D10: 1 | F10: 26-0034 | G10: GM Warren Tech Center Mazak Installation | H10: 1/14/2026 | J10: 93000 | K10: Warren, MI | L10: CON | M10: Dave Deller | R10: 0 | S10: 0 | T10: 356 | V10: 176 | W10: 532 | X10: 9000 | Y10: 4 | Z10: 26800 | AA10: 144 | AB10: 28061 | AC10: 30% | AD10: International Industrial Contracting Corp - 0 | AM10: 0 | AN10: 2541 | AV10: =IF(A10="Awarded",IFERROR((N10-J10)/J10,"-"),"-") -> -
A11: Open | B11: CCI Southeast MI | C11: Industrial/Power | D11: 1 | F11: 26-0025 | G11: The Barn - Warehouse | H11: 1/15/2026 | J11: 1747000 | K11: Saline, MI | L11: CON | M11: Joseph Leone | R11: 3461 | S11: 101806 | T11: 6267 | V11: 1394 | W11: 7661 | X11: 147151 | Y11: 12 | Z11: 151738 | AA11: 1146 | AB11: 218298 | AC11: 12% | AD11: La - 0 | AM11: 0 | AN11: 109099 | AV11: =IF(A11="Awarded",IFERROR((N11-J11)/J11,"-"),"-") -> -
A12: Open | B12: CCI Southeast MI | C12: Industrial/Power | D12: 1 | F12: 26-0026 | G12: The Barn - OPS Center | H12: 1/15/2026 | J12: 764000 | K12: Saline, MI | L12: CON | M12: Joseph Leone | R12: 1012 | S12: 39860 | T12: 2948 | V12: 1124 | W12: 4072 | X12: 79128 | Y12: 10 | Z12: 103541 | AA12: 832 | AB12: 148906 | AC12: 19% | AD12: La Salle - 0 | AM12: 0 | AN12: 42407 | AV12: =IF(A12="Awarded",IFERROR((N12-J12)/J12,"-"),"-") -> -
A13: Open | B13: CCI Southeast MI | C13: Other | D13: 1 | F13: 26-0031 | G13: Pinnacle Distribution Center Concrete | H13: 1/15/2026 | J13: 6277000 | K13: Romulus, MI | L13: CON | M13: Dave Deller | R13: 14474 | S13: 549916 | T13: 16748 | V13: 3888 | W13: 20636 | X13: 405000 | Y13: 24 | Z13: 329192 | AA13: 2496 | AB13: 561432 | AC13: 9% | AD13: Co - 0 Brinkmann - 0 Co;Brinkmann - 0 | AM13: 0 | AN13: 343432 | AV13: =IF(A13="Awarded",IFERROR((N13-J13)/J13,"-"),"-") -> -
A14: Open | B14: CCI Southeast MI | C14: Other | D14: 1 | F14: 26-0051 | G14: Project Lion - Wash Water Recycle System | H14: 1/16/2026 | J14: 320000 | K14: Detroit, MI | L14: CON | M14: Tucker Dye | R14: 330 | T14: 1358 | W14: 1358 | X14: 40341 | Y14: 4 | Z14: 46604 | AA14: 0 | AB14: 58051 | AC14: 18% | AD14: Shafer Redi - Mix - 0 | AM14: 0 | AN14: 42023 | AV14: =IF(A14="Awarded",IFERROR((N14-J14)/J14,"-"),"-") -> -
A15: Open | B15: CCI West Michigan | C15: Other | D15: 1 | F15: 26-0061 | G15: Amtrak Battle Creek Concrete | H15: 1/20/2026 | J15: 565500 | K15: Battle Creek, MI | L15: CON | M15: Greg Klem | P15: 0 | R15: 241 | S15: 6606 | T15: 2118 | V15: 2004 | W15: 4122 | X15: 68157 | Y15: 10 | Z15: 141026 | AA15: 880 | AB15: 176375 | AC15: 31% | AD15: George Allen Construction - 0 Krische Construction, Inc. - 0 Granite Construction Inc. - 0 | AM15: 0 | AN15: 32032 | AV15: =IF(A15="Awarded",IFERROR((N15-J15)/J15,"-"),"-") -> -
A16: Awarded | B16: CCI Southeast MI | C16: Industrial/Power | D16: 1 | E16: 251090 | F16: 25-0439 | G16: Woodland Meadows Culvert Concrete | H16: 1/8/2025 | I16: 5/22/2025 | J16: 243600 | K16: Van Buren Twp, MI | L16: CON | M16: Dave Deller | N16: 243600 | O16: 29760 | P16: 1176 | R16: 503 | S16: 14320 | T16: 876 | V16: 300 | W16: 1176 | X16: 29760 | Y16: 4 | Z16: 21171 | AA16: 256 | AB16: 23848 | AC16: 10% | AD16: D&R Earthmoving, LLC - 0 | AE16: 1385.5 | AF16: 230524 | AG16: 33376 | AH16: 263900 | AI16: 12.6% | AJ16: Open | AK16: 45778 | AM16: 0 | AN16: 11751 | AV16: =IF(A16="Awarded",IFERROR((N16-J16)/J16,"-"),"-") -> 0
A17: Closed | B17: CCI Southeast MI | C17: Historic Preservation | D17: 1 | F17: 25-0026 | G17: HFE Powerhouse Garage Pavilion Phase 2 - WC10 Concrete | H17: 1/15/2025 | J17: 1227000 | K17: Dearborn, MI | L17: CON | M17: Greg Klem | R17: 393 | S17: 11100 | T17: 4344 | V17: 2090 | W17: 6434 | X17: 129485 | Y17: 12 | Z17: 148602 | AA17: 1536 | AB17: 187322 | AC17: 15% | AD17: The Christman Company - 0 | AM17: 0 | AV17: =IF(A17="Awarded",IFERROR((N17-J17)/J17,"-"),"-") -> -
A18: Closed | B18: CCI Central MI | C18: Industrial/Power | D18: 1 | F18: 25-0069 | G18: Pfizer B225 Substation Reliability Expansion Concrete | H18: 1/24/2025 | J18: 157000 | K18: Portage, MI | L18: CON | M18: Greg Klem | R18: 101 | S18: 2600 | T18: 767 | V18: 456 | W18: 1223 | X18: 20501 | Y18: 4 | Z18: 33516 | AA18: 272 | AB18: 45400 | AC18: 29% | AD18: The Austin Company - 0 | AM18: 0 | AV18: =IF(A18="Awarded",IFERROR((N18-J18)/J18,"-"),"-") -> -
A19: Closed | B19: CCI Central MI | C19: Residential/ Housing | D19: 1 | F19: 25-0088 | G19: Tower on Grand | H19: 1/30/2025 | J19: 24497000 | K19: Lansing, MI | L19: CON | M19: Dave Deller | R19: 15580 | S19: 328652 | T19: 91256 | V19: 22300 | W19: 113556 | X19: 1800000 | Y19: 78 | Z19: 1971510 | AA19: 12792 | AB19: 2688042 | AC19: 11% | AD19: The Christman Company - 0 | AM19: 0 | AV19: =IF(A19="Awarded",IFERROR((N19-J19)/J19,"-"),"-") -> -
A20: Closed | B20: CCI Central MI | C20: Industrial/Power | D20: 1 | F20: 25-0087 | G20: Lansing Ave Pump Station and EQ Basin | H20: 1/30/2025 | J20: 8997000 | K20: Lansing, MI | L20: CON | M20: Dave Deller | R20: 7827 | S20: 55000 | T20: 20612 | V20: 10308 | W20: 30920 | X20: 997000 | Y20: 40 | Z20: 947600 | AA20: 5760 | AB20: 1491200 | AC20: 17% | AD20: FH Paschen - 0 Weiss - 0 FH Paschen;Weiss;FH Paschen;Weiss - 0 | AM20: 0 | AV20: =IF(A20="Awarded",IFERROR((N20-J20)/J20,"-"),"-") -> -
A21: Closed | B21: CCI Central MI | C21: Industrial/Power | D21: 2 | F21: 25-0137 | G21: Project Wolverine | H21: 2/14/2025 | J21: 6857000 | K21: Coldwater, MI | L21: CON | M21: Dave Deller | R21: 8522 | S21: 170000 | T21: 26297 | V21: 11096 | W21: 37393 | X21: 650000 | Y21: 40 | Z21: 800849 | AA21: 6160 | AB21: 1182911 | AC21: 17% | AD21: Gray Construction - 0 | AM21: 0 | AV21: =IF(A21="Awarded",IFERROR((N21-J21)/J21,"-"),"-") -> -
A22: Awarded | B22: CCI Southeast MI | C22: Industrial/Power | D22: 2 | E22: 251069 | F22: 25-0247 | G22: Jackson Tower Renovation | H22: 2/14/2025 | I22: 4/9/2025 | J22: 71284 | K22: Jackson, MI | L22: CON | M22: Farzan Rafieyan-Esfahani | N22: 71284 | O22: 10095 | P22: 450 | Q22: Bid was submitted via email to W.J. O'Neil on February 13th by Sean Webber on my behalf. | R22: 22 | T22: 326 | V22: 124 | W22: 450 | X22: 10095 | Y22: 2 | Z22: 8156 | AA22: 80 | AC22: 0% | AD22: W.J. O'Neil - 0 | AE22: 947 | AF22: 114591 | AG22: 11382 | AH22: 125973 | AI22: 9% | AJ22: Open | AK22: 45748 | AM22: 0 | AV22: =IF(A22="Awarded",IFERROR((N22-J22)/J22,"-"),"-") -> 0
A23: Closed | B23: CCI Southeast MI | C23: Other | D23: 2 | F23: 25-0153 | G23: WM Leachate Tank Concrete | H23: 2/21/2025 | J23: 57000 | K23: Van Buren, MI | L23: CON | M23: Greg Klem | R23: 71 | S23: 1640 | T23: 262 | V23: 98 | W23: 360 | X23: 10435 | Y23: 1 | Z23: 6893 | AA23: 80 | AB23: 9041 | AC23: 16% | AD23: D&R Earthmoving, LLC - 0 | AM23: 0 | AV23: =IF(A23="Awarded",IFERROR((N23-J23)/J23,"-"),"-") -> -
A24: Closed | B24: CCI Central MI | C24: Other | D24: 2 | F24: 25-0157 | G24: Site Concrete - Consumers Energy Lansing 9 | H24: 2/24/2025 | J24: 437000 | K24: Lansing, MI | L24: CON | M24: Ethan Conlan | R24: 400 | S24: 18000 | T24: 1666 | V24: 704 | W24: 2370 | X24: 49392 | Y24: 8 | Z24: 0 | AA24: 512 | AB24: 60278 | AC24: 14% | AD24: Consumers Energy - 0 | AM24: 0 | AV24: =IF(A24="Awarded",IFERROR((N24-J24)/J24,"-"),"-") -> -
A25: Awarded | B25: CCI Central MI | C25: Industrial/Power | D25: 2 | E25: 251048 | F25: 25-0160 | G25: Switch GRR02 Slab Trench Drains | H25: 2/26/2025 | I25: 3/6/2025 | J25: 880700 | K25: Caledonia, MI | L25: CON | M25: Greg Klem | N25: 846100 | O25: 76793 | P25: 4932 | R25: 220 | S25: 7690 | T25: 4256 | V25: 1012 | W25: 5268 | X25: 89823 | Y25: 10 | Z25: 90043 | AA25: 880 | AB25: 96033 | AC25: 11% | AD25: The Christman Company - 0 | AE25: 8624.75 | AF25: 888171 | AG25: 159811 | AH25: 1047982 | AI25: 15.2% | AJ25: Open | AK25: 45717 | AM25: 0 | AV25: =IF(A25="Awarded",IFERROR((N25-J25)/J25,"-"),"-") -> -0.039286931
A26: Awarded | B26: CCI Southeast MI | C26: Elem/High School | D26: 2 | E26: 251088 | F26: 25-0163 | G26: AAPS Thurston - WC05A Foundations | H26: 2/27/2025 | I26: 5/14/2025 | J26: 1879000 | K26: Ann Arbor, MI | L26: CON | M26: Greg Klem | N26: 1879000 | O26: 160107 | P26: 9022 | R26: 1986 | S26: 60000 | T26: 6718 | V26: 2304 | W26: 9022 | X26: 160107 | Y26: 16 | Z26: 170778 | AA26: 1536 | AB26: 227416 | AC26: 12% | AD26: The Christman Company - 0 | AE26: 9911.5 | AF26: 2190475 | AG26: -299630 | AH26: 1890845 | AI26: -15.8% | AJ26: Open | AK26: 45778 | AM26: 0 | AV26: =IF(A26="Awarded",IFERROR((N26-J26)/J26,"-"),"-") -> 0
A27: Closed | B27: CCI Southeast MI | C27: Elem/High School | D27: 2 | F27: 25-0164 | G27: AAPS Thurston WC05B Site Concrete | H27: 2/27/2025 | J27: 1069000 | K27: Ann Arbor, MI | L27: CON | M27: Greg Klem | R27: 1985 | S27: 73740 | T27: 3946 | V27: 1602 | W27: 5548 | X27: 110168 | Y27: 13 | Z27: 118161 | AA27: 1248 | AB27: 171869 | AC27: 16% | AD27: The Christman Company - 0 | AM27: 0 | AV27: =IF(A27="Awarded",IFERROR((N27-J27)/J27,"-"),"-") -> -
A28: Closed | B28: CCI Southeast MI | C28: Elem/High School | D28: 2 | F28: 25-0165 | G28: AAPS Thurston WC10 Interior Concrete Flatwork | H28: 2/27/2025 | J28: 1253000 | K28: Ann Arbor, MI | L28: CON | M28: Greg Klem | R28: 1107 | S28: 60000 | T28: 3392 | V28: 1128 | W28: 4520 | X28: 101110 | Y28: 8 | Z28: 83989 | AA28: 720 | AB28: 132088 | AC28: 11% | AD28: The Christman Company - 0 | AM28: 0 | AV28: =IF(A28="Awarded",IFERROR((N28-J28)/J28,"-"),"-") -> -
A29: Awarded | B29: CCI Central MI | C29: Government | D29: 2 | E29: 251073 | F29: 25-0170 | G29: Consumers Energy - City Gate - H-2 Highland | H29: 2/28/2025 | I29: 5/21/2025 | J29: 181458 | K29: Highland, MI | L29: CON | M29: Farzan Rafieyan-Esfahani | N29: 181458 | P29: 0 | R29: 174 | T29: 1077 | V29: 340 | W29: 1417 | X29: 23384 | Y29: 4 | Z29: 22830 | AA29: 288 | AB29: 33371 | AC29: 18% | AD29: Henkels & McCoy - 0 | AE29: 1268 | AF29: 155091 | AG29: 39448 | AH29: 194539 | AI29: 20.3% | AJ29: Hard Closed | AK29: 45748 | AL29: 45901 | AM29: 21 | AV29: =IF(A29="Awarded",IFERROR((N29-J29)/J29,"-"),"-") -> 0
A30: Awarded | B30: CCI Central MI | C30: Government | D30: 2 | E30: 251086 | F30: 25-0167 | G30: Consumers Energy - City Gate - B-1 Bancroft | H30: 2/28/2025 | I30: 5/28/2025 | J30: 123336 | K30: Byron, MI | L30: CON | M30: Farzan Rafieyan-Esfahani | N30: 123336 | O30: 16182 | P30: 1026 | Q30: Bid was submitted to Henkels & McCoy on February 28th via email. | R30: 70 | T30: 686 | V30: 340 | W30: 1026 | X30: 16182 | Y30: 4 | Z30: 22830 | AA30: 288 | AB30: 32696 | AC30: 27% | AD30: Henkels & McCoy - 0 | AE30: 664.5 | AF30: 80872 | AG30: 47128 | AH30: 128000 | AI30: 36.8% | AJ30: Open | AK30: 45778 | AM30: 0 | AV30: =IF(A30="Awarded",IFERROR((N30-J30)/J30,"-"),"-") -> 0
A31: Awarded | B31: CCI Central MI | C31: Government | D31: 2 | E31: 251078 | F31: 25-0168 | G31: Consumers Energy - City Gate - F-4 Flint | H31: 2/28/2025 | I31: 5/28/2025 | J31: 167188 | K31: Flint, MI | L31: CON | M31: Farzan Rafieyan-Esfahani | N31: 167188 | O31: 20575 | P31: 1166 | Q31: Bid was submitted to Henkels & McCoy on February 28th via email. | R31: 82 | T31: 826 | V31: 340 | W31: 1166 | X31: 20575 | Y31: 4 | Z31: 22830 | AA31: 288 | AB31: 33972 | AC31: 20% | AD31: Henkels & McCoy - 0 | AE31: 718.5 | AF31: 106093 | AG31: 65907 | AH31: 172000 | AI31: 38.3% | AJ31: Open | AK31: 45778 | AM31: 0 | AV31: =IF(A31="Awarded",IFERROR((N31-J31)/J31,"-"),"-") -> 0
A32: Closed | B32: CCI Central MI | C32: Government | D32: 2 | F32: 25-0169 | G32: Consumers Energy - City Gate - H-1 Hanover Horton | H32: 2/28/2025 | J32: 113310 | K32: Horton, MI | L32: CON | M32: Farzan Rafieyan-Esfahani | R32: 70 | T32: 612 | V32: 268 | W32: 880 | X32: 14511 | Y32: 3 | Z32: 17830 | AA32: 216 | AB32: 26998 | AC32: 24% | AD32: Henkels & McCoy - 0 | AM32: 0 | AV32: =IF(A32="Awarded",IFERROR((N32-J32)/J32,"-"),"-") -> -
A33: Closed | B33: Out of Region | C33: Industrial/Power | D33: 3 | F33: 25-0200 | G33: TC Energy TVA Rewheel Gas Cooler Project | H33: 3/10/2025 | J33: 738949 | K33: Hartsville, TN | L33: CON | M33: Frank Duff | R33: 410 | T33: 1753 | V33: 1436 | W33: 3189 | X33: 82811 | Y33: 12 | Z33: 104728 | AA33: 1376 | AB33: 212851 | AC33: 29% | AD33: Michels Pipeline, Inc. - 0 | AM33: 0 | AV33: =IF(A33="Awarded",IFERROR((N33-J33)/J33,"-"),"-") -> -
A34: Closed | B34: CCI Southeast MI | C34: Industrial/Power | D34: 3 | F34: 25-0196 | G34: Monroe WWTP | H34: 3/10/2025 | J34: 157100 | K34: Monroe, MI | L34: CON | M34: Greg Klem | R34: 14 | S34: 0 | T34: 464 | V34: 886 | W34: 1350 | X34: 22318 | Y34: 6 | Z34: 67734 | AA34: 656 | AB34: 75241 | AC34: 48% | AD34: FH Paschen - 0 | AM34: 0 | AV34: =IF(A34="Awarded",IFERROR((N34-J34)/J34,"-"),"-") -> -
A35: Closed | B35: CCI Central MI | C35: Health Care | D35: 3 | F35: 25-0283 | G35: Corewell Health Residency Housing | H35: 3/19/2025 | J35: 9367000 | K35: Grand Rapids, MI | L35: CON | M35: Dave Deller | R35: 13286 | S35: 181334 | T35: 24494 | V35: 9666 | W35: 34160 | X35: 720000 | Y35: 34 | Z35: 638321 | AA35: 5440 | AB35: 1493143 | AC35: 16% | AD35: Christman/ Spesh - 0 | AM35: 0 | AV35: =IF(A35="Awarded",IFERROR((N35-J35)/J35,"-"),"-") -> -
A36: Closed | B36: CCI Southeast MI | C36: Retail | D36: 3 | F36: 25-0246 | G36: Korex Addition | H36: 3/27/2025 | J36: 3317000 | K36: Wixom, MI | L36: CON | M36: Ethan Conlan | R36: 6726 | S36: 237000 | T36: 15836 | V36: 3518 | W36: 19354 | X36: 322266 | Y36: 19 | Z36: 259862 | AA36: 2792 | AB36: 334381 | AC36: 10% | AD36: Brinkmann - 0 | AM36: 0 | AV36: =IF(A36="Awarded",IFERROR((N36-J36)/J36,"-"),"-") -> -
A37: Closed | B37: CCI Central MI | C37: Government | D37: 4 | F37: 25-0281 | G37: Lansing City Hall BC 003B Foundations | H37: 4/2/2025 | J37: 449000 | K37: Lansing, MI | L37: CON | M37: Dave Deller | R37: 563 | S37: 26000 | T37: 1515 | V37: 1072 | W37: 2587 | X37: 42000 | Y37: 6 | Z37: 83906 | AA37: 672 | AB37: 83906 | AC37: 19% | AD37: Cl - 0 | AM37: 0 | AV37: =IF(A37="Awarded",IFERROR((N37-J37)/J37,"-"),"-") -> -
A38: Closed | B38: CCI Southeast MI | C38: Retail | D38: 4 | F38: 25-0282 | G38: QMI 1 PADDC Concrete | H38: 4/2/2025 | J38: 237000 | K38: Hazel Park, MI | L38: CON | M38: Dave Deller | R38: 100 | S38: 0 | T38: 827 | V38: 528 | W38: 1355 | X38: 25000 | Y38: 4 | Z38: 34446 | AA38: 416 | AB38: 49586 | AC38: 21% | AD38: KPRS Construction Services - 0 | AM38: 0 | AV38: =IF(A38="Awarded",IFERROR((N38-J38)/J38,"-"),"-") -> -
A39: Awarded | B39: CCI Central MI | C39: Government | D39: 4 | E39: 251084 | F39: 25-0280 | G39: Lansing City Hall BC003A Flatwork | H39: 4/2/2025 | I39: 5/16/2025 | J39: 543000 | K39: Lansing, MI | L39: CON | M39: Dave Deller | N39: 543000 | O39: 50000 | P39: 2993 | R39: 563 | S39: 65000 | T39: 2561 | V39: 432 | W39: 2993 | X39: 50000 | Y39: 4 | Z39: 26361 | AA39: 232 | AB39: 37940 | AC39: 7% | AD39: Clark Lansing - 0 | AE39: 3013.5 | AF39: 565850 | AG39: 87282 | AH39: 653132 | AI39: 13.4% | AJ39: Open | AK39: 45778 | AM39: 0 | AV39: =IF(A39="Awarded",IFERROR((N39-J39)/J39,"-"),"-") -> 0
A40: Closed | B40: CCI Central MI | C40: Office | D40: 4 | F40: 25-0277 | G40: Zoetis B248 Cafe Upgrade | H40: 4/2/2025 | J40: 166922 | K40: Kalamazoo, MI | L40: CON | M40: Farzan Rafieyan-Esfahani | R40: 144 | S40: 4715 | T40: 815 | V40: 284 | W40: 1099 | X40: 24089 | Y40: 4 | Z40: 19826 | AA40: 224 | AB40: 19826 | AC40: 12% | AD40: The Austin Company - 0 | AM40: 0 | AV40: =IF(A40="Awarded",IFERROR((N40-J40)/J40,"-"),"-") -> -
...

Sheet Data Dictionary
A1: Column Name | B1: Type | C1: Values / Format | D1: Purpose / Why It Matters
A2: Status ✅ | B2: Dropdown (existing) | C2: Awarded / Closed / Open | D2: Core outcome — determines if bid is included in hit rate calc
A3: Bid Amount ✅ | B3: Currency (existing) | C3: $#,##0 | D3: Our submitted price
A4: Contract Amount ✅ | B4: Currency (existing) | C4: $#,##0 | D4: Final contract value on awarded work
A5: Market Sector ✅ | B5: Text (existing) | C5: Healthcare, Industrial/Power, etc. | D5: Allows segmentation of win rates by project type
A6: Estimator ✅ | B6: Text (existing) | C6: Name | D6: Attribution for hit rate analysis per estimator
A7: Region ✅ | B7: Text (existing) | C7: CCI Southeast MI, etc. | D7: Regional performance comparison
A9: Delivery Method 🆕 | B9: Dropdown (NEW) | C9: Hard Bid / Negotiated / CM at Risk / Design-Build / Other | D9: CRITICAL — your negotiated hit rate is almost certainly far higher than hard bid. Mixing them distorts your ratio. Segment immediately.
A10: # of Bidders 🆕 | B10: Whole number (NEW) | C10: 1 – 20 | D10: Normalizes hit rate. 1 of 8 bidders at 12% is average; 1 of 2 at 50% is underperforming if you had the relationship.
A11: Opportunity Source 🆕 | B11: Dropdown (NEW) | C11: Existing Customer / Referral / Repeat Work / Cold RFP / Owner Direct / Other | D11: Identifies which lead sources convert best. Helps decide where estimating hours are worth spending.
A12: Go/No-Go Score 🆕 | B12: Dropdown (NEW) | C12: 1=Low / 2=Medium / 3=High | D12: Captures confidence AT TIME OF BID. Compare hit rate of Score-3 bids vs Score-1 — if they're similar, your scoring model needs work.
A13: Loss Reason 🆕 | B13: Dropdown (NEW) | C13: Price Too High / No Relationship / Scope Mismatch / Competitor Relationship / No-Bid After Review / Budget Cut / Unknown | D13: The single most valuable new column. Without this, 'Closed' is a black hole. Lets you distinguish pricing misses from unwinnable bids.
... A16: Bid Delta % 🆕 | B16: Formula (AUTO) | C16: Auto-calculated: (Contract − Bid) / Bid | D16: Shows how accurate your estimating is on wins. Consistently negative = leaving money on the table. Consistently high = you got lucky or scope changed.
